<?xml version="1.0" encoding="UTF-8"?>
<!-- Generated by org.testng.reporters.JUnitReportReporter -->
<testsuite hostname="DESKTOP-978OTPB" failures="4" tests="6" name="com.test.shlok.TestLogin" time="62.975" errors="0" timestamp="2022-03-31T17:52:51 IST" skipped="0">
  <testcase classname="com.test.shlok.TestLogin" name="positiveTC" time="14.400"/>
  <system-out>
    <![CDATA[LOGIN IS SUCCESSFUL
positiveTC is Passed
Test case is Pass]]>
  </system-out>
  <testcase classname="com.test.shlok.TestLogin" name="negativeTC_1" time="11.515">
    <failure message="The following asserts failed:
	expected [SHLOK | Admin Dashboard] but found [SHLOK]" type="java.lang.AssertionError">
      <![CDATA[java.lang.AssertionError: The following asserts failed:
expected [SHLOK | Admin Dashboard] but found [SHLOK]
at org.testng.asserts.SoftAssert.assertAll(SoftAssert.java:47)
at org.testng.asserts.SoftAssert.assertAll(SoftAssert.java:31)
at com.pages.shlok.LoginPage.loginWithBlankUNandPW(LoginPage.java:121)
at com.test.shlok.TestLogin.negativeTC_1(TestLogin.java:26)
at java.base/jdk.internal.reflect.NativeMethodAccessorImpl.invoke0(Native Method)
at java.base/jdk.internal.reflect.NativeMethodAccessorImpl.invoke(NativeMethodAccessorImpl.java:77)
at java.base/jdk.internal.reflect.DelegatingMethodAccessorImpl.invoke(DelegatingMethodAccessorImpl.java:43)
at java.base/java.lang.reflect.Method.invoke(Method.java:568)
at org.testng.internal.MethodInvocationHelper.invokeMethod(MethodInvocationHelper.java:133)
at org.testng.internal.TestInvoker.invokeMethod(TestInvoker.java:598)
at org.testng.internal.TestInvoker.invokeTestMethod(TestInvoker.java:173)
at org.testng.internal.MethodRunner.runInSequence(MethodRunner.java:46)
at org.testng.internal.TestInvoker$MethodInvocationAgent.invoke(TestInvoker.java:824)
at org.testng.internal.TestInvoker.invokeTestMethods(TestInvoker.java:146)
at org.testng.internal.TestMethodWorker.invokeTestMethods(TestMethodWorker.java:146)
at org.testng.internal.TestMethodWorker.run(TestMethodWorker.java:128)
at java.base/java.util.ArrayList.forEach(ArrayList.java:1511)
at org.testng.TestRunner.privateRun(TestRunner.java:794)
at org.testng.TestRunner.run(TestRunner.java:596)
at org.testng.SuiteRunner.runTest(SuiteRunner.java:377)
at org.testng.SuiteRunner.runSequentially(SuiteRunner.java:371)
at org.testng.SuiteRunner.privateRun(SuiteRunner.java:332)
at org.testng.SuiteRunner.run(SuiteRunner.java:276)
at org.testng.SuiteRunnerWorker.runSuite(SuiteRunnerWorker.java:53)
at org.testng.SuiteRunnerWorker.run(SuiteRunnerWorker.java:96)
at org.testng.TestNG.runSuitesSequentially(TestNG.java:1212)
at org.testng.TestNG.runSuitesLocally(TestNG.java:1134)
at org.testng.TestNG.runSuites(TestNG.java:1063)
at org.testng.TestNG.run(TestNG.java:1031)
at org.testng.remote.AbstractRemoteTestNG.run(AbstractRemoteTestNG.java:115)
at org.testng.remote.RemoteTestNG.initAndRun(RemoteTestNG.java:251)
at org.testng.remote.RemoteTestNG.main(RemoteTestNG.java:77)
]]>
    </failure>
  </testcase> <!-- negativeTC_1 -->
  <system-out>
    <![CDATA[LOGIN IS NOT SUCCESSFUL DUE TO BLANK UN and PW
negativeTC_1 is Failed
Test Case is Fail]]>
  </system-out>
  <testcase classname="com.test.shlok.TestLogin" name="negativeTC_2" time="9.137"/>
  <system-out>
    <![CDATA[Correct Error Message for Unsuccessful Login Is Shown i.e : Username and password were incorrect
negativeTC_2 is Passed
Test case is Pass]]>
  </system-out>
  <testcase classname="com.test.shlok.TestLogin" name="negativeTC_3" time="9.238">
    <failure message="The following asserts failed:
	expected [SHLOK | Admin Dashboard] but found [SHLOK]" type="java.lang.AssertionError">
      <![CDATA[java.lang.AssertionError: The following asserts failed:
expected [SHLOK | Admin Dashboard] but found [SHLOK]
at org.testng.asserts.SoftAssert.assertAll(SoftAssert.java:47)
at org.testng.asserts.SoftAssert.assertAll(SoftAssert.java:31)
at com.pages.shlok.LoginPage.loginWithInvalidPW(LoginPage.java:91)
at com.test.shlok.TestLogin.negativeTC_3(TestLogin.java:38)
at java.base/jdk.internal.reflect.NativeMethodAccessorImpl.invoke0(Native Method)
at java.base/jdk.internal.reflect.NativeMethodAccessorImpl.invoke(NativeMethodAccessorImpl.java:77)
at java.base/jdk.internal.reflect.DelegatingMethodAccessorImpl.invoke(DelegatingMethodAccessorImpl.java:43)
at java.base/java.lang.reflect.Method.invoke(Method.java:568)
at org.testng.internal.MethodInvocationHelper.invokeMethod(MethodInvocationHelper.java:133)
at org.testng.internal.TestInvoker.invokeMethod(TestInvoker.java:598)
at org.testng.internal.TestInvoker.invokeTestMethod(TestInvoker.java:173)
at org.testng.internal.MethodRunner.runInSequence(MethodRunner.java:46)
at org.testng.internal.TestInvoker$MethodInvocationAgent.invoke(TestInvoker.java:824)
at org.testng.internal.TestInvoker.invokeTestMethods(TestInvoker.java:146)
at org.testng.internal.TestMethodWorker.invokeTestMethods(TestMethodWorker.java:146)
at org.testng.internal.TestMethodWorker.run(TestMethodWorker.java:128)
at java.base/java.util.ArrayList.forEach(ArrayList.java:1511)
at org.testng.TestRunner.privateRun(TestRunner.java:794)
at org.testng.TestRunner.run(TestRunner.java:596)
at org.testng.SuiteRunner.runTest(SuiteRunner.java:377)
at org.testng.SuiteRunner.runSequentially(SuiteRunner.java:371)
at org.testng.SuiteRunner.privateRun(SuiteRunner.java:332)
at org.testng.SuiteRunner.run(SuiteRunner.java:276)
at org.testng.SuiteRunnerWorker.runSuite(SuiteRunnerWorker.java:53)
at org.testng.SuiteRunnerWorker.run(SuiteRunnerWorker.java:96)
at org.testng.TestNG.runSuitesSequentially(TestNG.java:1212)
at org.testng.TestNG.runSuitesLocally(TestNG.java:1134)
at org.testng.TestNG.runSuites(TestNG.java:1063)
at org.testng.TestNG.run(TestNG.java:1031)
at org.testng.remote.AbstractRemoteTestNG.run(AbstractRemoteTestNG.java:115)
at org.testng.remote.RemoteTestNG.initAndRun(RemoteTestNG.java:251)
at org.testng.remote.RemoteTestNG.main(RemoteTestNG.java:77)
]]>
    </failure>
  </testcase> <!-- negativeTC_3 -->
  <system-out>
    <![CDATA[LOGIN IS NOT SUCCESSFUL
negativeTC_3 is Failed
Test Case is Fail]]>
  </system-out>
  <testcase classname="com.test.shlok.TestLogin" name="negativeTC_4" time="8.795">
    <failure message="The following asserts failed:
	expected [SHLOK | Admin Dashboard] but found [SHLOK]" type="java.lang.AssertionError">
      <![CDATA[java.lang.AssertionError: The following asserts failed:
expected [SHLOK | Admin Dashboard] but found [SHLOK]
at org.testng.asserts.SoftAssert.assertAll(SoftAssert.java:47)
at org.testng.asserts.SoftAssert.assertAll(SoftAssert.java:31)
at com.pages.shlok.LoginPage.loginWithInvalidUN(LoginPage.java:105)
at com.test.shlok.TestLogin.negativeTC_4(TestLogin.java:44)
at java.base/jdk.internal.reflect.NativeMethodAccessorImpl.invoke0(Native Method)
at java.base/jdk.internal.reflect.NativeMethodAccessorImpl.invoke(NativeMethodAccessorImpl.java:77)
at java.base/jdk.internal.reflect.DelegatingMethodAccessorImpl.invoke(DelegatingMethodAccessorImpl.java:43)
at java.base/java.lang.reflect.Method.invoke(Method.java:568)
at org.testng.internal.MethodInvocationHelper.invokeMethod(MethodInvocationHelper.java:133)
at org.testng.internal.TestInvoker.invokeMethod(TestInvoker.java:598)
at org.testng.internal.TestInvoker.invokeTestMethod(TestInvoker.java:173)
at org.testng.internal.MethodRunner.runInSequence(MethodRunner.java:46)
at org.testng.internal.TestInvoker$MethodInvocationAgent.invoke(TestInvoker.java:824)
at org.testng.internal.TestInvoker.invokeTestMethods(TestInvoker.java:146)
at org.testng.internal.TestMethodWorker.invokeTestMethods(TestMethodWorker.java:146)
at org.testng.internal.TestMethodWorker.run(TestMethodWorker.java:128)
at java.base/java.util.ArrayList.forEach(ArrayList.java:1511)
at org.testng.TestRunner.privateRun(TestRunner.java:794)
at org.testng.TestRunner.run(TestRunner.java:596)
at org.testng.SuiteRunner.runTest(SuiteRunner.java:377)
at org.testng.SuiteRunner.runSequentially(SuiteRunner.java:371)
at org.testng.SuiteRunner.privateRun(SuiteRunner.java:332)
at org.testng.SuiteRunner.run(SuiteRunner.java:276)
at org.testng.SuiteRunnerWorker.runSuite(SuiteRunnerWorker.java:53)
at org.testng.SuiteRunnerWorker.run(SuiteRunnerWorker.java:96)
at org.testng.TestNG.runSuitesSequentially(TestNG.java:1212)
at org.testng.TestNG.runSuitesLocally(TestNG.java:1134)
at org.testng.TestNG.runSuites(TestNG.java:1063)
at org.testng.TestNG.run(TestNG.java:1031)
at org.testng.remote.AbstractRemoteTestNG.run(AbstractRemoteTestNG.java:115)
at org.testng.remote.RemoteTestNG.initAndRun(RemoteTestNG.java:251)
at org.testng.remote.RemoteTestNG.main(RemoteTestNG.java:77)
]]>
    </failure>
  </testcase> <!-- negativeTC_4 -->
  <system-out>
    <![CDATA[LOGIN IS NOT SUCCESSFUL
negativeTC_4 is Failed
Test Case is Fail]]>
  </system-out>
  <testcase classname="com.test.shlok.TestLogin" name="negativeTC_5" time="9.890">
    <failure message="The following asserts failed:
	expected [SHLOK | Admin Dashboard] but found [SHLOK]" type="java.lang.AssertionError">
      <![CDATA[java.lang.AssertionError: The following asserts failed:
expected [SHLOK | Admin Dashboard] but found [SHLOK]
at org.testng.asserts.SoftAssert.assertAll(SoftAssert.java:47)
at org.testng.asserts.SoftAssert.assertAll(SoftAssert.java:31)
at com.pages.shlok.LoginPage.loginWithWrongUN(LoginPage.java:138)
at com.test.shlok.TestLogin.negativeTC_5(TestLogin.java:50)
at java.base/jdk.internal.reflect.NativeMethodAccessorImpl.invoke0(Native Method)
at java.base/jdk.internal.reflect.NativeMethodAccessorImpl.invoke(NativeMethodAccessorImpl.java:77)
at java.base/jdk.internal.reflect.DelegatingMethodAccessorImpl.invoke(DelegatingMethodAccessorImpl.java:43)
at java.base/java.lang.reflect.Method.invoke(Method.java:568)
at org.testng.internal.MethodInvocationHelper.invokeMethod(MethodInvocationHelper.java:133)
at org.testng.internal.TestInvoker.invokeMethod(TestInvoker.java:598)
at org.testng.internal.TestInvoker.invokeTestMethod(TestInvoker.java:173)
at org.testng.internal.MethodRunner.runInSequence(MethodRunner.java:46)
at org.testng.internal.TestInvoker$MethodInvocationAgent.invoke(TestInvoker.java:824)
at org.testng.internal.TestInvoker.invokeTestMethods(TestInvoker.java:146)
at org.testng.internal.TestMethodWorker.invokeTestMethods(TestMethodWorker.java:146)
at org.testng.internal.TestMethodWorker.run(TestMethodWorker.java:128)
at java.base/java.util.ArrayList.forEach(ArrayList.java:1511)
at org.testng.TestRunner.privateRun(TestRunner.java:794)
at org.testng.TestRunner.run(TestRunner.java:596)
at org.testng.SuiteRunner.runTest(SuiteRunner.java:377)
at org.testng.SuiteRunner.runSequentially(SuiteRunner.java:371)
at org.testng.SuiteRunner.privateRun(SuiteRunner.java:332)
at org.testng.SuiteRunner.run(SuiteRunner.java:276)
at org.testng.SuiteRunnerWorker.runSuite(SuiteRunnerWorker.java:53)
at org.testng.SuiteRunnerWorker.run(SuiteRunnerWorker.java:96)
at org.testng.TestNG.runSuitesSequentially(TestNG.java:1212)
at org.testng.TestNG.runSuitesLocally(TestNG.java:1134)
at org.testng.TestNG.runSuites(TestNG.java:1063)
at org.testng.TestNG.run(TestNG.java:1031)
at org.testng.remote.AbstractRemoteTestNG.run(AbstractRemoteTestNG.java:115)
at org.testng.remote.RemoteTestNG.initAndRun(RemoteTestNG.java:251)
at org.testng.remote.RemoteTestNG.main(RemoteTestNG.java:77)
]]>
    </failure>
  </testcase> <!-- negativeTC_5 -->
  <system-out>
    <![CDATA[LOGIN IS NOT SUCCESSFUL
negativeTC_5 is Failed
Test Case is Fail]]>
  </system-out>
</testsuite> <!-- com.test.shlok.TestLogin -->
